<?xml version="1.0" encoding="UTF-8"?>
<robot name="weed_robot" xmlns:xacro="http://www.ros.org/wiki/xacro">

<xacro:arg name="meshes" default="true"/>

<xacro:include filename="$(find weed_robot_description)/urdf/material.xacro"/>
<xacro:include filename="$(find weed_robot_description)/urdf/macro.xacro"/>

<xacro:property name="config_yaml" value="$(find weed_robot_description)/config/weed_robot.yaml"/>
<xacro:property name="config" value="${load_yaml(config_yaml)}"/>

<!-- Base -->
<link name="base_link_vis"/>

<!-- Chassis -->
<link name="chassis_link">
  <inertial>
    <origin xyz="0 0 0" rpy="0 0 0"/>
    <mass value="${config['chassis']['mass']}"/>
    <xacro:box_inertia link_config="${config['chassis']}"/>
  </inertial>
  <visual>
    <origin xyz="0 0 0" rpy="0 0 0"/>
    <geometry>
      <xacro:if value="$(arg meshes)">
        <mesh filename="package://weed_robot_description/meshes/chassis.stl"/>
      </xacro:if>
      <xacro:unless value="$(arg meshes)">
        <xacro:box_geometry link_config="${config['chassis']}"/>
      </xacro:unless>
    </geometry>
    <material name="grey"/>
  </visual>
  <collision>
    <origin xyz="0 0 0" rpy="0 0 0"/>
    <geometry>
      <xacro:box_geometry link_config="${config['chassis']}"/>
    </geometry>
  </collision>
</link>
<gazebo reference="chassis_link">
  <visual>
    <material>
      <xacro:gmaterial color="grey"/>
    </material>
  </visual>
</gazebo>
<joint name="base_chassis_joint" type="fixed">
  <parent link="base_link_vis"/>
  <child link="chassis_link"/>
  <origin xyz="0.791 0 0.83" rpy="0 0 0"/>
</joint>

<!-- Panels -->
<link name="panels_link">
  <inertial>
    <origin xyz="0 0 0" rpy="0 0 0"/>
    <mass value="${config['panels']['mass']}"/>
    <xacro:box_inertia link_config="${config['panels']}"/>
  </inertial>
  <visual>
    <origin xyz="0 0 0" rpy="0 0 0"/>
    <geometry>
      <xacro:if value="$(arg meshes)">
        <!-- <mesh filename="package://weed_robot_description/meshes/panels.stl"/> -->
        <mesh filename="package://weed_robot_description/meshes/panels.dae"/>
      </xacro:if>
      <xacro:unless value="$(arg meshes)">
        <xacro:box_geometry link_config="${config['panels']}"/>
      </xacro:unless>
    </geometry>
    <material name="blue"/>
  </visual>
  <collision>
    <origin xyz="0 0 0" rpy="0 0 0"/>
    <geometry>
      <xacro:box_geometry link_config="${config['panels']}"/>
    </geometry>
  </collision>
</link>
<!-- <gazebo reference="panels_link">
  <visual>
    <material>
      <xacro:gmaterial color="blue"/>
    </material>
  </visual>
</gazebo> -->
<joint name="chassis_panels_joint" type="fixed">
  <parent link="chassis_link"/>
  <child link="panels_link"/>
  <origin xyz="0 0 0.1875" rpy="0 0 0"/>
</joint>

<!-- Sprayers -->
<link name="sprayers_link">
  <inertial>
    <origin xyz="0 0 0" rpy="0 0 0"/>
    <mass value="${config['sprayers']['mass']}"/>
    <xacro:box_inertia link_config="${config['sprayers']}"/>
  </inertial>
  <visual>
    <origin xyz="0 0 0" rpy="0 0 0"/>
    <geometry>
      <xacro:if value="$(arg meshes)">
        <mesh filename="package://weed_robot_description/meshes/sprayers.stl"/>
      </xacro:if>
      <xacro:unless value="$(arg meshes)">
        <xacro:box_geometry link_config="${config['sprayers']}"/>
      </xacro:unless>
    </geometry>
    <material name="dark_grey"/>
  </visual>
  <collision>
    <origin xyz="0 0 0" rpy="0 0 0"/>
    <geometry>
      <xacro:box_geometry link_config="${config['sprayers']}"/>
    </geometry>
  </collision>
</link>
<gazebo reference="sprayers_link">
  <visual>
    <material>
      <xacro:gmaterial color="dark_grey"/>
    </material>
  </visual>
</gazebo>
<joint name="chassis_sprayers_joint" type="fixed">
  <parent link="chassis_link"/>
  <child link="sprayers_link"/>
  <origin xyz="-1.216 0 -0.080" rpy="0 0 0"/>
</joint>

<!-- Fork front-left -->
<link name="fork_fl_link">
  <inertial>
    <origin xyz="0 0 0" rpy="0 0 0"/>
    <mass value="${config['fork']['mass']}"/>
    <xacro:box_inertia link_config="${config['fork']}"/>
  </inertial>
  <visual>
    <origin xyz="0 0 0" rpy="0 0 0"/>
    <geometry>
      <xacro:if value="$(arg meshes)">
        <mesh filename="package://weed_robot_description/meshes/fork.stl"/>
      </xacro:if>
      <xacro:unless value="$(arg meshes)">
        <xacro:box_geometry link_config="${config['fork']}"/>
      </xacro:unless>
    </geometry>
    <material name="dark_grey"/>
  </visual>
  <collision>
    <origin xyz="0 0 0" rpy="0 0 0"/>
    <geometry>
      <xacro:box_geometry link_config="${config['fork']}"/>
    </geometry>
  </collision>
</link>
<gazebo reference="fork_fl_link">
  <visual>
    <material>
      <xacro:gmaterial color="dark_grey"/>
    </material>
  </visual>
</gazebo>
<joint name="chassis_fork_fl_joint" type="revolute">
  <parent link="chassis_link"/>
  <child link="fork_fl_link"/>
  <origin xyz="0.791 0.527 -0.292" rpy="0 0 0"/>
  <axis xyz="0 0 1"/>
  <limit lower="${-28.391/180*pi}" upper="${40.186/180*pi}" effort="1000" velocity="0.01"/> <!-- calculado con radio de giro 2.40m -->
  <safety_controller soft_lower_limit="${-27.986/180*pi}" soft_upper_limit="${39.443/180*pi}" k_velocity="10" k_position="15"/> <!-- calculado con radio de giro 2.45m -->
</joint>

<!-- Fork front-right -->
<link name="fork_fr_link">
  <inertial>
    <origin xyz="0 0 0" rpy="0 0 0"/>
    <mass value="${config['fork']['mass']}"/>
    <xacro:box_inertia link_config="${config['fork']}"/>
  </inertial>
  <visual>
    <origin xyz="0 0 0" rpy="0 0 0"/>
    <geometry>
      <xacro:if value="$(arg meshes)">
        <mesh filename="package://weed_robot_description/meshes/fork.stl"/>
      </xacro:if>
      <xacro:unless value="$(arg meshes)">
        <xacro:box_geometry link_config="${config['fork']}"/>
      </xacro:unless>
    </geometry>
    <material name="dark_grey"/>
  </visual>
  <collision>
    <origin xyz="0 0 0" rpy="0 0 0"/>
    <geometry>
      <xacro:box_geometry link_config="${config['fork']}"/>
    </geometry>
  </collision>
</link>
<gazebo reference="fork_fr_link">
  <visual>
    <material>
      <xacro:gmaterial color="dark_grey"/>
    </material>
  </visual>
</gazebo>
<joint name="chassis_fork_fr_joint" type="revolute">
  <parent link="chassis_link"/>
  <child link="fork_fr_link"/>
  <origin xyz="0.791 -0.527 -0.292" rpy="0 0 0"/>
  <axis xyz="0 0 1"/>
  <limit lower="${-40.186/180*pi}" upper="${28.391/180*pi}" effort="1000" velocity="0.01"/>
  <safety_controller soft_lower_limit="${-39.443/180*pi}" soft_upper_limit="${27.986/180*pi}" k_velocity="10" k_position="15"/>
</joint>

<!-- Steer -->
<link name="steer_link"/>
<joint name="chassis_steer_joint" type="revolute">
  <parent link="chassis_link"/>
  <child link="steer_link"/>
  <origin xyz="0.791 0 -0.292" rpy="0 0 0"/>
  <axis xyz="0 0 1"/>
  <limit lower="${-33.392/180*pi}" upper="${33.392/180*pi}" effort="1000" velocity="0.01"/>
  <safety_controller soft_lower_limit="${-32.851/180*pi}" soft_upper_limit="${32.851/180*pi}" k_velocity="10" k_position="15"/>
</joint>

<!-- Fork rear-left -->
<link name="fork_rl_link">
  <inertial>
    <origin xyz="0 0 0" rpy="0 0 0"/>
    <mass value="${config['fork']['mass']}"/>
    <xacro:box_inertia link_config="${config['fork']}"/>
  </inertial>
  <visual>
    <origin xyz="0 0 0" rpy="0 0 0"/>
    <geometry>
      <xacro:if value="$(arg meshes)">
        <mesh filename="package://weed_robot_description/meshes/fork.stl"/>
      </xacro:if>
      <xacro:unless value="$(arg meshes)">
        <xacro:box_geometry link_config="${config['fork']}"/>
      </xacro:unless>
    </geometry>
    <material name="dark_grey"/>
  </visual>
  <collision>
    <origin xyz="0 0 0" rpy="0 0 0"/>
    <geometry>
      <xacro:box_geometry link_config="${config['fork']}"/>
    </geometry>
  </collision>
</link>
<gazebo reference="fork_rl_link">
  <visual>
    <material>
      <xacro:gmaterial color="dark_grey"/>
    </material>
  </visual>
</gazebo>
<joint name="chassis_fork_rl_joint" type="fixed">
  <parent link="chassis_link"/>
  <child link="fork_rl_link"/>
  <origin xyz="-0.791 0.527 -0.292" rpy="0 0 0"/>
</joint>

<!-- Fork rear-right -->
<link name="fork_rr_link">
  <inertial>
    <origin xyz="0 0 0" rpy="0 0 0"/>
    <mass value="${config['fork']['mass']}"/>
    <xacro:box_inertia link_config="${config['fork']}"/>
  </inertial>
  <visual>
    <origin xyz="0 0 0" rpy="0 0 0"/>
    <geometry>
      <xacro:if value="$(arg meshes)">
        <mesh filename="package://weed_robot_description/meshes/fork.stl"/>
      </xacro:if>
      <xacro:unless value="$(arg meshes)">
        <xacro:box_geometry link_config="${config['fork']}"/>
      </xacro:unless>
    </geometry>
    <material name="dark_grey"/>
  </visual>
  <collision>
    <origin xyz="0 0 0" rpy="0 0 0"/>
    <geometry>
      <xacro:box_geometry link_config="${config['fork']}"/>
    </geometry>
  </collision>
</link>
<gazebo reference="fork_rr_link">
  <visual>
    <material>
      <xacro:gmaterial color="dark_grey"/>
    </material>
  </visual>
</gazebo>
<joint name="chassis_fork_rr_joint" type="fixed">
  <parent link="chassis_link"/>
  <child link="fork_rr_link"/>
  <origin xyz="-0.791 -0.527 -0.292" rpy="0 0 0"/>
</joint>

<!-- Wheel front-left -->
<link name="wheel_fl_link">
  <inertial>
    <origin xyz="0 0 0" rpy="0 0 0"/>
    <mass value="${config['wheel']['mass']}"/>
    <xacro:cylinder_inertia link_config="${config['wheel']}"/>
  </inertial>
  <visual>
    <xacro:if value="$(arg meshes)">
      <origin xyz="0 0 0" rpy="0 0 0"/>
      <geometry>
        <mesh filename="package://weed_robot_description/meshes/wheel.stl"/>
      </geometry>
    </xacro:if>
    <xacro:unless value="$(arg meshes)">
      <origin xyz="0 0 0" rpy="1.5708 0 0"/>
      <geometry>
        <xacro:cylinder_geometry link_config="${config['wheel']}"/>
      </geometry>
    </xacro:unless>
    <material name="black"/>
  </visual>
  <collision>
    <origin xyz="0 0 0" rpy="1.5708 0 0"/>
    <geometry>
      <xacro:cylinder_geometry link_config="${config['wheel']}"/>
    </geometry>
  </collision>
</link>
<gazebo reference="wheel_fl_link">
  <kp value="${config['wheel']['kp']}"/>
  <kd value="${config['wheel']['kd']}"/>
  <mu1 value="${config['wheel']['mu1']}"/>
  <mu2 value="${config['wheel']['mu2']}"/>
  <visual>
    <material>
      <xacro:gmaterial color="black"/>
    </material>
  </visual>
</gazebo>
<joint name="fork_wheel_fl_joint" type="continuous">
  <parent link="fork_fl_link"/>
  <child link="wheel_fl_link"/>
  <origin xyz="0.041 0 -0.266" rpy="0 0 0" />
  <axis xyz="0 1 0"/>
</joint>

<!-- Wheel front-right -->
<link name="wheel_fr_link">
  <inertial>
    <origin xyz="0 0 0" rpy="0 0 0"/>
    <mass value="${config['wheel']['mass']}"/>
    <xacro:cylinder_inertia link_config="${config['wheel']}"/>
  </inertial>
  <visual>
    <xacro:if value="$(arg meshes)">
      <origin xyz="0 0 0" rpy="0 0 0"/>
      <geometry>
        <mesh filename="package://weed_robot_description/meshes/wheel.stl"/>
      </geometry>
    </xacro:if>
    <xacro:unless value="$(arg meshes)">
      <origin xyz="0 0 0" rpy="1.5708 0 0"/>
      <geometry>
        <xacro:cylinder_geometry link_config="${config['wheel']}"/>
      </geometry>
    </xacro:unless>
    <material name="black"/>
  </visual>
  <collision>
    <origin xyz="0 0 0" rpy="1.5708 0 0"/>
    <geometry>
      <xacro:cylinder_geometry link_config="${config['wheel']}"/>
    </geometry>
  </collision>
</link>
<gazebo reference="wheel_fr_link">
  <kp value="${config['wheel']['kp']}"/>
  <kd value="${config['wheel']['kd']}"/>
  <mu1 value="${config['wheel']['mu1']}"/>
  <mu2 value="${config['wheel']['mu2']}"/>
  <visual>
    <material>
      <xacro:gmaterial color="black"/>
    </material>
  </visual>
</gazebo>
<joint name="fork_wheel_fr_joint" type="continuous">
  <parent link="fork_fr_link"/>
  <child link="wheel_fr_link"/>
  <origin xyz="0.041 0 -0.266" rpy="0 0 0" />
  <axis xyz="0 1 0"/>
</joint>

<!-- Wheel rear-left -->
<link name="wheel_rl_link">
  <inertial>
    <origin xyz="0 0 0" rpy="0 0 0"/>
    <mass value="${config['wheel']['mass']}"/>
    <xacro:cylinder_inertia link_config="${config['wheel']}"/>
  </inertial>
  <visual>
    <xacro:if value="$(arg meshes)">
      <origin xyz="0 0 0" rpy="0 0 0"/>
      <geometry>
        <mesh filename="package://weed_robot_description/meshes/wheel.stl"/>
      </geometry>
    </xacro:if>
    <xacro:unless value="$(arg meshes)">
      <origin xyz="0 0 0" rpy="1.5708 0 0"/>
      <geometry>
        <xacro:cylinder_geometry link_config="${config['wheel']}"/>
      </geometry>
    </xacro:unless>
    <material name="black"/>
  </visual>
  <collision>
    <origin xyz="0 0 0" rpy="1.5708 0 0"/>
    <geometry>
      <xacro:cylinder_geometry link_config="${config['wheel']}"/>
    </geometry>
  </collision>
</link>
<gazebo reference="wheel_rl_link">
  <kp value="${config['wheel']['kp']}"/>
  <kd value="${config['wheel']['kd']}"/>
  <mu1 value="${config['wheel']['mu1']}"/>
  <mu2 value="${config['wheel']['mu2']}"/>
  <visual>
    <material>
      <xacro:gmaterial color="black"/>
    </material>
  </visual>
</gazebo>
<joint name="fork_wheel_rl_joint" type="continuous">
  <parent link="fork_rl_link"/>
  <child link="wheel_rl_link"/>
  <origin xyz="0.041 0 -0.266" rpy="0 0 0" />
  <axis xyz="0 1 0"/>
</joint>

<!-- Wheel rear-right -->
<link name="wheel_rr_link">
  <inertial>
    <origin xyz="0 0 0" rpy="0 0 0"/>
    <mass value="${config['wheel']['mass']}"/>
    <xacro:cylinder_inertia link_config="${config['wheel']}"/>
  </inertial>
  <visual>
    <xacro:if value="$(arg meshes)">
      <origin xyz="0 0 0" rpy="0 0 0"/>
      <geometry>
        <mesh filename="package://weed_robot_description/meshes/wheel.stl"/>
      </geometry>
    </xacro:if>
    <xacro:unless value="$(arg meshes)">
      <origin xyz="0 0 0" rpy="1.5708 0 0"/>
      <geometry>
        <xacro:cylinder_geometry link_config="${config['wheel']}"/>
      </geometry>
    </xacro:unless>
    <material name="black"/>
  </visual>
  <collision>
    <origin xyz="0 0 0" rpy="1.5708 0 0"/>
    <geometry>
      <xacro:cylinder_geometry link_config="${config['wheel']}"/>
    </geometry>
  </collision>
</link>
<gazebo reference="wheel_rr_link">
  <kp value="${config['wheel']['kp']}"/>
  <kd value="${config['wheel']['kd']}"/>
  <mu1 value="${config['wheel']['mu1']}"/>
  <mu2 value="${config['wheel']['mu2']}"/>
  <visual>
    <material>
      <xacro:gmaterial color="black"/>
    </material>
  </visual>
</gazebo>
<joint name="fork_wheel_rr_joint" type="continuous">
  <parent link="fork_rr_link"/>
  <child link="wheel_rr_link"/>
  <origin xyz="0.041 0 -0.266" rpy="0 0 0" />
  <axis xyz="0 1 0"/>
</joint>

<!-- Wheel -->
<link name="wheel_link">
  <inertial>
    <origin xyz="0 0 0" rpy="0 0 0"/>
    <mass value="${config['wheel']['mass']}"/>
    <xacro:cylinder_inertia link_config="${config['wheel']}"/>
  </inertial>
  <collision>
    <origin xyz="0 0 0" rpy="1.5708 0 0"/>
    <geometry>
      <xacro:cylinder_geometry link_config="${config['wheel']}"/>
    </geometry>
  </collision>
</link>
<joint name="chassis_wheel_joint" type="continuous">
  <parent link="chassis_link"/>
  <child link="wheel_link"/>
  <origin xyz="-0.791 0 -0.558" rpy="0 0 0"/>
  <axis xyz="0 1 0"/>
</joint>

</robot>